Workbook

Sheet Guardian
A1: FirstName | B1: LastName | C1: MRN | D1: AccountNumber | E1: VisitNumber | F1: PhoneNumber | G1: CellphoneNumber | H1: EmailAddress | I1: DateOfBirth
A2: NO SIBLING GUARDIAN | B2: TESTING | C2: G231 | D2: G231 | E2: G231 | I2: 27051
A3: GUARDIAN FOR TWIN | B3: TIMELESS | C3: G123 | D3: G123 | E3: G123 | F3: 1111111111 | G3: 2222222222 | H3: sampleguardian@mail.com | I3: 27051

Sheet Patient
A1: FirstName | B1: MiddleName | C1: LastName | D1: DateOfBirth | E1: MRNNumber | F1: AccountNumber | G1: VisitNumber | H1: MPID | I1: Room | J1: Bed | K1: MotherIdentifier | L1: UseForTesting
A2: NO SIBLING | C2: TESTING | D2: 45344 | E2: 12345 | F2: 12345 | G2: 12345 | H2: 12345 | I2: 300 | J2: 003 | K2: G231 | L2: 1
A3: TWIN BABY A | C3: TIMELESS | E3: 123 | F3: 123 | G3: 123 | H3: 123 | I3: 100 | J3: 001 | K3: =Guardian!C3 -> G123
A4: TWIN BABY B | C4: TIMELESS | E4: 1234 | F4: 1234 | G4: 1234 | H4: 1234 | I4: 200 | J4: 002 | K4: G123

Sheet Order
A1: Order Name | B1: Order Base | C1: Milk Base / Base Product | D1: Base Product ShortName | E1: Base Product Cal | F1: Feed Volume | G1: Frequency | H1: Label Notes | I1: Additive Name | J1: Short Name | K1: Is Modular | L1: Mix To Cal or Modular Value
A2: EHM + Fortifiers | B2: Breastmilk | F2: 10 | H2: EHM + Fortifiers Label Note
I3: Enfamil Infant PWD | J3: =IF(VLOOKUP(I3, OrderAdditives!A:B, 2, FALSE)=0, "", VLOOKUP(I3, OrderAdditives!A:B, 2, FALSE)) -> Enfamil Infant | K3: FALSE | L3: =IFERROR(ROUND(IF(Setup!B2=Setup!F1, 22*Setup!F2, IF(Setup!B2=Setup!E1, 22*Setup!E2, IF(Setup!B2=Setup!D1, 22*Setup!D2, 0))), IF(Setup!B2=Setup!D1, 0, Setup!B3)), 0) -> 22
I4: Mct Oil Concentrate | J4: =IF(VLOOKUP(I4, OrderAdditives!A:B, 2, FALSE)=0, "", VLOOKUP(I4, OrderAdditives!A:B, 2, FALSE)) -> MCT Oil | K4: FALSE | L4: =IFERROR(ROUND(IF(Setup!B2=Setup!F1, 24*Setup!F2, IF(Setup!B2=Setup!E1, 24*Setup!E2, IF(Setup!B2=Setup!D1, 24*Setup!D2, 0))), IF(Setup!B2=Setup!D1, 0, Setup!B3)), 0) -> 24
A5: EHM +Fortifier + Modular | B5: Breastmilk | F5: 10 | H5: EHM + Fortifier + Modular Label Note
I6: Enfamil Infant PWD | J6: =IF(VLOOKUP(I6, OrderAdditives!A:B, 2, FALSE)=0, "", VLOOKUP(I6, OrderAdditives!A:B, 2, FALSE)) -> Enfamil Infant | K6: FALSE | L6: =IFERROR(ROUND(IF(Setup!B2=Setup!F1, 22*Setup!F2, IF(Setup!B2=Setup!E1, 22*Setup!E2, IF(Setup!B2=Setup!D1, 22*Setup!D2, 0))), IF(Setup!B2=Setup!D1, 0, Setup!B3)), 0) -> 22
I7: Mct Oil Concentrate | J7: =IF(VLOOKUP(I7, OrderAdditives!A:B, 2, FALSE)=0, "", VLOOKUP(I7, OrderAdditives!A:B, 2, FALSE)) -> MCT Oil | K7: TRUE | L7: 0.2
A8: DHM + Fortifiers | B8: Breastmilk | F8: 10 | H8: EHM + Fortifiers Label Note
I9: Enfamil Infant PWD | J9: =IF(VLOOKUP(I9, OrderAdditives!A:B, 2, FALSE)=0, "", VLOOKUP(I9, OrderAdditives!A:B, 2, FALSE)) -> Enfamil Infant | K9: FALSE | L9: =IFERROR(ROUND(IF(Setup!B2=Setup!F1, 22*Setup!F2, IF(Setup!B2=Setup!E1, 22*Setup!E2, IF(Setup!B2=Setup!D1, 22*Setup!D2, 0))), IF(Setup!B2=Setup!D1, 0, Setup!B3)), 0) -> 22
I10: Mct Oil Concentrate | J10: =IF(VLOOKUP(I10, OrderAdditives!A:B, 2, FALSE)=0, "", VLOOKUP(I10, OrderAdditives!A:B, 2, FALSE)) -> MCT Oil | K10: FALSE | L10: =IFERROR(ROUND(IF(Setup!B2=Setup!F1, 24*Setup!F2, IF(Setup!B2=Setup!E1, 24*Setup!E2, IF(Setup!B2=Setup!D1, 24*Setup!D2, 0))), IF(Setup!B2=Setup!D1, 0, Setup!B3)), 0) -> 24
A11: DHM +Fortifier + Modular | B11: Breastmilk | F11: 10 | H11: EHM + Fortifier + Modular Label Note
I12: Enfamil Infant PWD | J12: =IF(VLOOKUP(I12, OrderAdditives!A:B, 2, FALSE)=0, "", VLOOKUP(I12, OrderAdditives!A:B, 2, FALSE)) -> Enfamil Infant | K12: FALSE | L12: =IFERROR(ROUND(IF(Setup!B2=Setup!F1, 22*Setup!F2, IF(Setup!B2=Setup!E1, 22*Setup!E2, IF(Setup!B2=Setup!D1, 22*Setup!D2, 0))), IF(Setup!B2=Setup!D1, 0, Setup!B3)), 0) -> 22
I13: Mct Oil Concentrate | J13: =IF(VLOOKUP(I13, OrderAdditives!A:B, 2, FALSE)=0, "", VLOOKUP(I13, OrderAdditives!A:B, 2, FALSE)) -> MCT Oil | K13: TRUE | L13: 0.2
A14: EHM or DHM + Fortifiers | B14: Breastmilk | F14: 10 | H14: EHM + Fortifiers Label Note
I15: Enfamil Infant PWD | J15: =IF(VLOOKUP(I15, OrderAdditives!A:B, 2, FALSE)=0, "", VLOOKUP(I15, OrderAdditives!A:B, 2, FALSE)) -> Enfamil Infant | K15: FALSE | L15: =IFERROR(ROUND(IF(Setup!B2=Setup!F1, 22*Setup!F2, IF(Setup!B2=Setup!E1, 22*Setup!E2, IF(Setup!B2=Setup!D1, 22*Setup!D2, 0))), IF(Setup!B2=Setup!D1, 0, Setup!B3)), 0) -> 22
I16: Mct Oil Concentrate | J16: =IF(VLOOKUP(I16, OrderAdditives!A:B, 2, FALSE)=0, "", VLOOKUP(I16, OrderAdditives!A:B, 2, FALSE)) -> MCT Oil | K16: FALSE | L16: =IFERROR(ROUND(IF(Setup!B2=Setup!F1, 24*Setup!F2, IF(Setup!B2=Setup!E1, 24*Setup!E2, IF(Setup!B2=Setup!D1, 24*Setup!D2, 0))), IF(Setup!B2=Setup!D1, 0, Setup!B3)), 0) -> 24
A17: EHM or DHM + Fortifier + Modular | B17: Breastmilk | F17: 10 | H17: EHM + Fortifiers Label Note
I18: Enfamil Infant PWD | J18: =IF(VLOOKUP(I18, OrderAdditives!A:B, 2, FALSE)=0, "", VLOOKUP(I18, OrderAdditives!A:B, 2, FALSE)) -> Enfamil Infant | K18: FALSE | L18: =IFERROR(ROUND(IF(Setup!B2=Setup!F1, 22*Setup!F2, IF(Setup!B2=Setup!E1, 22*Setup!E2, IF(Setup!B2=Setup!D1, 22*Setup!D2, 0))), IF(Setup!B2=Setup!D1, 0, Setup!B3)), 0) -> 22
I19: Mct Oil Concentrate | J19: =IF(VLOOKUP(I19, OrderAdditives!A:B, 2, FALSE)=0, "", VLOOKUP(I19, OrderAdditives!A:B, 2, FALSE)) -> MCT Oil | K19: TRUE | L19: 0.2
A20: Product without Fortifier | B20: Product | C20: Enfamil Infant RTU | D20: =IF(VLOOKUP(C20, 'Order Base'!A:B, 2, FALSE)=0, "", VLOOKUP(C20, 'Order Base'!A:B, 2, FALSE)) -> Enfamil Infant | E20: =VLOOKUP(C20, 'Order Base'!A:C, 3, FALSE) -> 20 | F20: 10 | H20: Product without Fortifier Label Note
A21: Product + Fortifiers | B21: Product | C21: Enfamil Infant RTU | D21: =IF(VLOOKUP(C21, 'Order Base'!A:B, 2, FALSE)=0, "", VLOOKUP(C21, 'Order Base'!A:B, 2, FALSE)) -> Enfamil Infant | E21: =VLOOKUP(C21, 'Order Base'!A:C, 3, FALSE) -> 20 | F21: 10 | H21: Product + Fortifier Label Note
I22: Enfamil Infant PWD | J22: =IF(VLOOKUP(I22, OrderAdditives!A:B, 2, FALSE)=0, "", VLOOKUP(I22, OrderAdditives!A:B, 2, FALSE)) -> Enfamil Infant | K22: FALSE | L22: =IFERROR(ROUND(IF(Setup!B2=Setup!F1, 22*Setup!F2, IF(Setup!B2=Setup!E1, 22*Setup!E2, IF(Setup!B2=Setup!D1, 22*Setup!D2, 0))), IF(Setup!B2=Setup!D1, 0, Setup!B3)), 0) -> 22
I23: Mct Oil Concentrate | J23: =IF(VLOOKUP(I23, OrderAdditives!A:B, 2, FALSE)=0, "", VLOOKUP(I23, OrderAdditives!A:B, 2, FALSE)) -> MCT Oil | K23: FALSE | L23: =IFERROR(ROUND(IF(Setup!B2=Setup!F1, 24*Setup!F2, IF(Setup!B2=Setup!E1, 24*Setup!E2, IF(Setup!B2=Setup!D1, 24*Setup!D2, 0))), IF(Setup!B2=Setup!D1, 0, Setup!B3)), 0) -> 24
A24: Product + Fortifier + Modular | B24: Product | C24: Enfamil Infant RTU | D24: =IF(VLOOKUP(C24, 'Order Base'!A:B, 2, FALSE)=0, "", VLOOKUP(C24, 'Order Base'!A:B, 2, FALSE)) -> Enfamil Infant | E24: =VLOOKUP(C24, 'Order Base'!A:C, 3, FALSE) -> 20 | F24: 10 | H24: Product + Fortifier + Modular Label Note
I25: Enfamil Infant PWD | J25: =IF(VLOOKUP(I25, OrderAdditives!A:B, 2, FALSE)=0, "", VLOOKUP(I25, OrderAdditives!A:B, 2, FALSE)) -> Enfamil Infant | K25: FALSE | L25: =IFERROR(ROUND(IF(Setup!B2=Setup!F1, 22*Setup!F2, IF(Setup!B2=Setup!E1, 22*Setup!E2, IF(Setup!B2=Setup!D1, 22*Setup!D2, 0))), IF(Setup!B2=Setup!D1, 0, Setup!B3)), 0) -> 22
I26: Mct Oil Concentrate | J26: =IF(VLOOKUP(I26, OrderAdditives!A:B, 2, FALSE)=0, "", VLOOKUP(I26, OrderAdditives!A:B, 2, FALSE)) -> MCT Oil | K26: TRUE | L26: 0.2
A27: Sterile Water + Fortifiers | B27: Sterile Water | C27: Similac Sterile Water | D27: =IF(VLOOKUP(C27, 'Order Base'!A:B, 2, FALSE)=0, "", VLOOKUP(C27, 'Order Base'!A:B, 2, FALSE)) -> Sim Sterile Water | E27: =VLOOKUP(C27, 'Order Base'!A:C, 3, FALSE) -> 0 | F27: 10 | H27: Sterile Water + Fortifier Label Note
I28: Enfamil Infant PWD | J28: =IF(VLOOKUP(I28, OrderAdditives!A:B, 2, FALSE)=0, "", VLOOKUP(I28, OrderAdditives!A:B, 2, FALSE)) -> Enfamil Infant | K28: FALSE | L28: =IFERROR(ROUND(IF(Setup!B2=Setup!F1, 20*Setup!F2, IF(Setup!B2=Setup!E1, 20*Setup!E2, IF(Setup!B2=Setup!D1, 20*Setup!D2, 0))), IF(Setup!B2=Setup!D1, 0, Setup!B3)), 0) -> 20
I29: Mct Oil Concentrate | J29: =IF(VLOOKUP(I29, OrderAdditives!A:B, 2, FALSE)=0, "", VLOOKUP(I29, OrderAdditives!A:B, 2, FALSE)) -> MCT Oil | K29: FALSE | L29: =IFERROR(ROUND(IF(Setup!B2=Setup!F1, 22*Setup!F2, IF(Setup!B2=Setup!E1, 22*Setup!E2, IF(Setup!B2=Setup!D1, 22*Setup!D2, 0))), IF(Setup!B2=Setup!D1, 0, Setup!B3)), 0) -> 22
A30: Sterile Water + Fortifier + Modular | B30: Sterile Water | C30: Similac Sterile Water | D30: =IF(VLOOKUP(C30, 'Order Base'!A:B, 2, FALSE)=0, "", VLOOKUP(C30, 'Order Base'!A:B, 2, FALSE)) -> Sim Sterile Water | E30: =VLOOKUP(C30, 'Order Base'!A:C, 3, FALSE) -> 0 | F30: 10 | H30: Sterile Water + Fortifier + Modular Label Note
I31: Enfamil Infant PWD | J31: =IF(VLOOKUP(I31, OrderAdditives!A:B, 2, FALSE)=0, "", VLOOKUP(I31, OrderAdditives!A:B, 2, FALSE)) -> Enfamil Infant | K31: FALSE | L31: =IFERROR(ROUND(IF(Setup!B2=Setup!F1, 20*Setup!F2, IF(Setup!B2=Setup!E1, 20*Setup!E2, IF(Setup!B2=Setup!D1, 20*Setup!D2, 0))), IF(Setup!B2=Setup!D1, 0, Setup!B3)), 0) -> 20
I32: Mct Oil Concentrate | J32: =IF(VLOOKUP(I32, OrderAdditives!A:B, 2, FALSE)=0, "", VLOOKUP(I32, OrderAdditives!A:B, 2, FALSE)) -> MCT Oil | K32: TRUE | L32: 0.2

Sheet Order Base
A1: formtypeName | B1: formtypeShortName | C1: formtypeCalPerOz
A2: Enfamil Infant RTU | B2: Enfamil Infant | C2: 20
A3: Enfamil NeuroPro Infant RTU | B3: Enfamil NeuroPro Infant | C3: 20
A4: Enfamil NeuroPro EnfaCare RTU | B4: NeuroPro Enfacare | C4: 22
A5: Enfamil EnfaCare RTU | C5: 22
A6: Enfamil NeuroPro Gentlease RTU | C6: 20
A7: Enfamil A.R. RTU | B7: Enfamil A.R | C7: 20
A8: Nutramigen RTU | C8: 20
A9: Pregestimil 24 kcal RTU | C9: 24
A10: Pregestimil 20 kcal RTU | C10: 20
A11: Enfamil ProSobee RTU | C11: 20
A12: Enfagrow NeuroPro Toddler Natural Milk Nutritional Drink | C12: 20
A13: Enfagrow NeuroPro Toddler Vanilla Flavor Nutrition Drink | C13: 20
A14: Enfamil Water, Oral Use RTU | C14: 0
A15: Enfamil 5% Glucose Water RTU | C15: 5.91
A16: Enfamil Enfalyte Oral Electrolyte Solution RTU | C16: 3.7
A17: Enfamil Premature with Iron 20 kcal RTU | C17: 20
A18: Enfamil Premature 24 kcal RTU | C18: 24
A19: Enfamil Premature 30 kcal RTU | C19: 30
... A22: Enfaport Nursette RTU | C22: 30
A23: Similac With Iron 24 | B23: Sim Iron 24 | C23: 24
A24: Similac Advance RTF | C24: 20
A25: Pure Bliss Organic RTF | B25: Pure Bliss Organic | C25: 20
A26: Similac 360 Total Care RTF | B26: Sim 360 Total | C26: 20
A27: Similac 360 Total Care Sensitive RTF | B27: Sim 360 Total | C27: 20
A28: Similac Special Care 20 RTU | B28: Sim Special Care 20 | C28: 20
A29: Similac Special Care 24 RTU | B29: Sim Special Care 24 | C29: 24
A30: Similac Special Care 24 High Protein RTU | B30: Sim Special Care 24 HP | C30: 24
A31: Similac Special Care 30 RTF | B31: Sim Special Care 30 | C31: 32.53
A32: Similac Neosure RTF | B32: Sim Neosure | C32: 22
A33: Neocate Splash | B33: Neocate Splash | C33: 30
A34: Similac Alimentum RTF | B34: Sim Alimentum | C34: 20
A35: Similac Pro-Total Comfort 20 RTF | B35: Sim Pro-Total Comfort 20 | C35: 20
A36: Similac Sensitive for Spit-Up RTF | B36: Sim Sensitive Spit Up | C36: 20
... A40: Nepro with Carbsteady | B40: Nepro Carbsteady | C40: 53
A41: Pedialyte Classic | C41: 3
A42: Glucerna 1.5 Cal | C42: 44
A43: Glucerna | C43: 28
A44: Pediasure Grow & Gain | C44: 30
A45: Pediasure 1.5 | C45: 45
...

Sheet OrderAdditives
A1: formtypeName | B1: formtypeShortName
A2: Enfamil Infant RTU | B2: Enfamil Infant
A3: Enfamil Infant Concentrate | B3: Enfamil Infant
A4: Enfamil Infant PWD | B4: Enfamil Infant
A5: Enfamil NeuroPro Infant RTU | B5: Enfamil NeuroPro Infant
A6: Enfamil NeuroPro Infant PWD | B6: Enfamil NeuroPro Infant
A7: Enfamil Enspire Optimum PWD | B7: Enfamil Enspire
A8: Enfamil Enspire Gentlease PWD | B8: Enfamil Enspire Gentlease
A9: Enfamil NeuroPro EnfaCare RTU | B9: NeuroPro Enfacare
A10: Enfamil NeuroPro EnfaCare PWD
A11: Enfamil EnfaCare RTU
A12: Enfamil Gentlease PWD | B12: Enfamil Gentlease
A13: Enfamil NeuroPro Gentlease PWD
A14: Enfamil NeuroPro Gentlease RTU
A15: Enfamil A.R. RTU | B15: Enfamil A.R
A16: Enfamil A.R. PWD
A17: Enfamil NeuroPro Sensitive PWD
A18: Nutramigen RTU
A19: Nutramigen Concentrate Liquid
A20: Nutramigen with Enflora LGG PWD Can
A21: Pregestimil PWD
A22: Pregestimil 24 kcal RTU
A23: Pregestimil 20 kcal RTU
A24: Enfamil ProSobee RTU
A25: Enfamil ProSobee Concentrate Liquid
A26: Enfamil ProSobee PWD
A27: Enfamil Reguline PWD
... A45: Enfamil 24 kcal RTU
A46: Phenyl-Free 1 | B46: Phenyl-Free 1
A47: BCAD 1 | B47: BCAD 1
A48: GA | B48: GA
A49: HCY 1 | B49: HCY 1
A50: LMD | B50: LMD
A51: PFD Toddler | B51: PFD Toddler
A52: TYROS 1 | B52: TYROS 1
A53: OA 1 | B53: OA 1
A54: WND 1 | B54: WND 1
A55: Phenyl-Free 2 | B55: Phenyl-Free 2
A56: Phenyl-Free 2HP | B56: Phenyl-Free 2HP
A57: BCAD 2 | B57: BCAD 2
...

Sheet Setup
A1: Settings Name | B1: VALUE | D1: KCAL_PER_OZ_DEFAULT | E1: KCAL_PER_ML | F1: KCAL_PER_100_MLS | H1: Scenario Name | I1: Product Name
A2: cal_per_oz_unit_conversion | B2: KCAL_PER_OZ_DEFAULT | D2: 1 | E2: =1 / 29.5735296 -> 0.033814023 | F2: =1 / (29.5735296 / 100) -> 3.3814023 | H2: Split Powder Product to Assigned Patient | I2: Enfamil Infant PWD
A3: ui/decimal/rounding/cals | B3: 0 | H3: Split Powder Product to Unassigned Patient | I3: Enfamil Infant PWD
H4: Split Received RTU Product to Assigned Patient | I4: Enfamil Infant RTU
